Workbook
Name Emissions: #REF!
Name Emissions: #REF!
Name Emissions: #REF!
Name Emissions: #REF!
Name Emissions: #REF!
Name Emissions: #REF!
Name Emissions: #REF!
Name Emissions: #REF!
Name Emissions: #REF!
Name Emissions: #REF!
Name Emissions: #REF!
Name Fuels: [1]Data!$C$2:$C$24
Name Fuels: [1]Data!$C$2:$C$24
Name Fuels: [1]Data!$C$2:$C$24
Name Fuels: #REF!
Name Fuels: #REF!
Name Fuels: [2]Data!$C$2:$C$24
Name Fuels: [1]Data!$C$2:$C$24
Name Fuels: #REF!
Name Fuels: #REF!
Name Fuels: [1]Data!$C$2:$C$24
Name Fuels: #REF!
Name Fuels: [3]Data!$C$2:$C$24
Name Fuels: [3]Data!$C$2:$C$24
Name Fuels: [2]Data!$C$2:$C$24
Name Fuels: [2]Data!$C$2:$C$24
Name Fuels: #REF!
Name Regions: [1]Data!$G$2:$G$11
Name Regions: [1]Data!$G$2:$G$11
Name Regions: [1]Data!$G$2:$G$11
Name Regions: #REF!
Name Regions: #REF!
Name Regions: [2]Data!$G$2:$G$11
Name Regions: [1]Data!$G$2:$G$11
Name Regions: #REF!
Name Regions: #REF!
Name Regions: [1]Data!$G$2:$G$11
Name Regions: #REF!
Name Regions: [3]Data!$G$2:$G$11
Name Regions: [3]Data!$G$2:$G$11
Name Regions: [2]Data!$G$2:$G$11
Name Regions: [2]Data!$G$2:$G$11
Name Regions: #REF!
Name Storages: #REF!
Name Storages: #REF!
Name Storages: #REF!
Name Storages: #REF!
Name Storages: #REF!
Name Storages: #REF!
Name Storages: #REF!
Name Storages: #REF!
Name Storages: #REF!
Name Storages: #REF!
Name Storages: #REF!
Name Technologies: #REF!:B
Name Technologies: #REF!:B
Name Technologies: #REF!:B
Name Technologies: #REF!:B
Name Technologies: [2]Data!#REF!:B
Name Technologies: [4]Data!$B$2:$B$83

Sheet Sets
A1: Emission | B1: Technology | C1: Fuel | D1: Year | E1: Timeslice | F1: Mode_of_operation | G1: Region | H1: Season | I1: Daytype | J1: Daylitimebracket | K1: Storage | L1: ModalType | M1: obsolete | N1: Sectors
A2: CO2 | B2: A_Air | C2: Area_Rooftop_Commercial | D2: 2018 | E2: Q1M | F2: 1 | G2: AT | H2: 1 | I2: 1 | J2: 1 | K2: S_PHS | L2: MT_PSNG_ROAD | M2: HHT_Biomass | N2: Power
B3: A_Rooftop_Commercial | C3: Area_Rooftop_Residential | D3: 2025 | E3: Q1P | F3: 2 | G3: BE | H3: 2 | J3: 2 | K3: S_Gas_H2 | L3: MT_PSNG_RAIL | M3: HHT_Coal_Hardcoal | N3: Industry
B4: A_Rooftop_Residential | C4: Biomass | D4: 2030 | E4: Q1A | F4: 3 | G4: BG | H4: 3 | J4: 3 | K4: S_Battery_Li-Ion | L4: MT_PSNG_AIR | M4: HHT_Coal_Lignite | N4: Buildings
B5: CHP_Biomass_Solid | C5: Hardcoal | D5: 2035 | E5: Q1N | F5: 4 | G5: CH | H5: 4 | J5: 4 | K5: S_Battery_Redox | L5: MT_PSNG_ROAD_RE | M5: HHT_Electric_Furnace | N5: Transportation
B6: CHP_Biomass_Solid_CCS | C6: H2 | D6: 2040 | E6: Q2M | G6: CZ | K6: S_Heat_HLR | L6: MT_PSNG_RAIL_RE | M6: HHT_Gas | N6: Resources
B7: CHP_Coal_Hardcoal | C7: Gas_Natural | D7: 2045 | E7: Q2P | G7: DE | K7: S_Heat_HLI | L7: MT_PSNG_AIR_RE | M7: HHT_Geothermal | N7: Storages
B8: CHP_Coal_Hardcoal_CCS | C8: Nuclear | D8: 2050 | E8: Q2A | G8: DK | K8: S_CAES | L8: MT_PSNG_ROAD_CONV | M8: HHT_Oil | N8: Transformation
B9: CHP_Coal_Lignite | C9: Oil | E9: Q2N | G9: EE | K9: S_Gas_Methane | L9: MT_PSNG_RAIL_CONV | M9: HHT_H2 | N9: CHP
B10: CHP_Coal_Lignite_CCS | C10: Power | E10: Q3M | G10: ES | L10: MT_PSNG_AIR_CONV | M10: HLT_Biomass
B11: CHP_Gas_CCGT_Biogas | C11: Mobility_Freight | E11: Q3P | G11: FI | L11: MT_FRT_ROAD | M11: HLT_Coal_Hardcoal
B12: CHP_Gas_CCGT_Biogas_CCS | C12: Mobility_Passenger | E12: Q3A | G12: FR | L12: MT_FRT_RAIL | M12: HLT_Coal_Lignite
B13: CHP_Gas_CCGT_Natural | C13: Lignite | E13: Q3N | G13: GR | L13: MT_FRT_ROAD_RE | M13: HLT_Electric_Furnace
B14: CHP_Gas_CCGT_Natural_CCS | C14: Gas_Bio | E14: Q4M | G14: HR | L14: MT_FRT_ROAD_CONV | M14: HLT_Gas
B15: CHP_Gas_CCGT_SynGas | C15: Gas_Synth | E15: Q4P | G15: HU | L15: MT_FRT_RAIL_RE | M15: HLT_Geothermal
B16: CHP_Hydrogen_FuelCell | C16: Heat_Low_Residential | E16: Q4A | G16: IE | L16: MT_FRT_RAIL_CONV | M16: HLT_Heatpump
B17: CHP_Oil | C17: Heat_Low_Industrial | E17: Q4N | G17: IT | L17: MT_FRT_SHIP | M17: HLT_Oil
B18: D_Battery_Li-Ion | C18: Heat_Medium_Industrial | G18: LT | L18: MT_FRT_SHIP_CONV | M18: HLT_Rooftop_Commercial
B19: D_Battery_Redox | C19: Heat_High_Industrial | G19: LU | L19: MT_FRT_SHIP_RE | M19: HLT_Rooftop_Residential
B20: D_CAES | C20: Biofuel | G20: LV | M20: CHP_Nuclear
B21: D_Gas_H2 | C21: Powerfuel | G21: NL | M21: CHP_Biomass
B22: D_Gas_Methane | C22: LNG | G22: NO | M22: CHP_Coal_Hardcoal
B23: D_Heat_HLI | C23: LBG | G23: PL | M23: CHP_Coal_Lignite
B24: D_Heat_HLR | C24: LSG | G24: PT | M24: CHP_Gas
B25: D_PHS | C25: LH2 | G25: RO
B26: D_PHS_Residual | C26: Air | G26: SE
B27: FRT_Rail_Conv | C27: Powerfuel | G27: SI
B28: FRT_Rail_Electric | C28: DAC_Dummy | G28: SK
B29: FRT_Road_BEV | C29: ETS | G29: TR
B30: FRT_Road_H2 | C30: ETS_Source | G30: UK
B31: FRT_Road_ICE | C31: Heat_District | G31: NONEU_Balkan
B32: FRT_Road_LNG
B33: FRT_Road_OH
B34: FRT_Road_PHEV
B35: FRT_Ship_Bio
B36: FRT_Ship_Conv
B37: FRT_Ship_LNG
B38: HLI_Convert_DH
B39: HLR_Convert_DH
B40: HHI_BF_BOF
...

Sheet Par_DaySplit
A1: YearSplit{l in TIMESLICE, y in YEAR} Units: Fraction of 8760 hours
A2: The fraction of the year in each time slice.
A3: Unit: Fraction of 8760 hours
A5: Year | B5: Q1N | C5: Q1M | D5: Q1P | E5: Q1A | F5: Q2N | G5: Q2M | H5: Q2P | I5: Q2A | J5: Q3N | K5: Q3M | L5: Q3P | M5: Q3A | N5: Q4N | O5: Q4M | P5: Q4P | Q5: Q4A
A6: 2018 | B6: 0.0016552511 | C6: 0.00017123288 | D6: 0.000456621 | E6: 0.000456621 | F6: 0.00091324201 | G6: 0.00034246575 | H6: 0.00091324201 | I6: 0.00057077626 | J6: 0.0010844749 | K6: 0.0002283105 | L6: 0.00079908676 | M6: 0.00062785388 | N6: 0.0017694064 | O6: 0.00039954338 | P6: 0.00028538813 | Q6: 0.00028538813
A7: 2020 | B7: 0.0016552511 | C7: 0.00017123288 | D7: 0.000456621 | E7: 0.000456621 | F7: 0.00091324201 | G7: 0.00034246575 | H7: 0.00091324201 | I7: 0.00057077626 | J7: 0.0010844749 | K7: 0.0002283105 | L7: 0.00079908676 | M7: 0.00062785388 | N7: 0.0017694064 | O7: 0.00039954338 | P7: 0.00028538813 | Q7: 0.00028538813
A8: 2025 | B8: 0.0016552511 | C8: 0.00017123288 | D8: 0.000456621 | E8: 0.000456621 | F8: 0.00091324201 | G8: 0.00034246575 | H8: 0.00091324201 | I8: 0.00057077626 | J8: 0.0010844749 | K8: 0.0002283105 | L8: 0.00079908676 | M8: 0.00062785388 | N8: 0.0017694064 | O8: 0.00039954338 | P8: 0.00028538813 | Q8: 0.00028538813
A9: 2030 | B9: 0.0016552511 | C9: 0.00017123288 | D9: 0.000456621 | E9: 0.000456621 | F9: 0.00091324201 | G9: 0.00034246575 | H9: 0.00091324201 | I9: 0.00057077626 | J9: 0.0010844749 | K9: 0.0002283105 | L9: 0.00079908676 | M9: 0.00062785388 | N9: 0.0017694064 | O9: 0.00039954338 | P9: 0.00028538813 | Q9: 0.00028538813
A10: 2035 | B10: 0.0016552511 | C10: 0.00017123288 | D10: 0.000456621 | E10: 0.000456621 | F10: 0.00091324201 | G10: 0.00034246575 | H10: 0.00091324201 | I10: 0.00057077626 | J10: 0.0010844749 | K10: 0.0002283105 | L10: 0.00079908676 | M10: 0.00062785388 | N10: 0.0017694064 | O10: 0.00039954338 | P10: 0.00028538813 | Q10: 0.00028538813
A11: 2040 | B11: 0.0016552511 | C11: 0.00017123288 | D11: 0.000456621 | E11: 0.000456621 | F11: 0.00091324201 | G11: 0.00034246575 | H11: 0.00091324201 | I11: 0.00057077626 | J11: 0.0010844749 | K11: 0.0002283105 | L11: 0.00079908676 | M11: 0.00062785388 | N11: 0.0017694064 | O11: 0.00039954338 | P11: 0.00028538813 | Q11: 0.00028538813
A12: 2045 | B12: 0.0016552511 | C12: 0.00017123288 | D12: 0.000456621 | E12: 0.000456621 | F12: 0.00091324201 | G12: 0.00034246575 | H12: 0.00091324201 | I12: 0.00057077626 | J12: 0.0010844749 | K12: 0.0002283105 | L12: 0.00079908676 | M12: 0.00062785388 | N12: 0.0017694064 | O12: 0.00039954338 | P12: 0.00028538813 | Q12: 0.00028538813
A13: 2050 | B13: 0.0016552511 | C13: 0.00017123288 | D13: 0.000456621 | E13: 0.000456621 | F13: 0.00091324201 | G13: 0.00034246575 | H13: 0.00091324201 | I13: 0.00057077626 | J13: 0.0010844749 | K13: 0.0002283105 | L13: 0.00079908676 | M13: 0.00062785388 | N13: 0.0017694064 | O13: 0.00039954338 | P13: 0.00028538813 | Q13: 0.00028538813

Sheet Par_YearSplit
A1: YearSplit{l in TIMESLICE, y in YEAR}
A2: The fraction of the year in each time slice.
A3: Unit: Fraction of 8760 hours
A5: Timeslice | B5: 2018 | C5: 2020 | D5: 2025 | E5: 2030 | F5: 2035 | G5: 2040 | H5: 2045 | I5: 2050
A6: Q1N | B6: 0.15104167 | C6: 0.15104167 | D6: 0.15104167 | E6: 0.15104167 | F6: 0.15104167 | G6: 0.15104167 | H6: 0.15104167 | I6: 0.15104167
A7: Q1M | B7: 0.015625 | C7: 0.015625 | D7: 0.015625 | E7: 0.015625 | F7: 0.015625 | G7: 0.015625 | H7: 0.015625 | I7: 0.015625
A8: Q1P | B8: 0.041666667 | C8: 0.041666667 | D8: 0.041666667 | E8: 0.041666667 | F8: 0.041666667 | G8: 0.041666667 | H8: 0.041666667 | I8: 0.041666667
A9: Q1A | B9: 0.041666667 | C9: 0.041666667 | D9: 0.041666667 | E9: 0.041666667 | F9: 0.041666667 | G9: 0.041666667 | H9: 0.041666667 | I9: 0.041666667
A10: Q2N | B10: 0.083333333 | C10: 0.083333333 | D10: 0.083333333 | E10: 0.083333333 | F10: 0.083333333 | G10: 0.083333333 | H10: 0.083333333 | I10: 0.083333333
A11: Q2M | B11: 0.03125 | C11: 0.03125 | D11: 0.03125 | E11: 0.03125 | F11: 0.03125 | G11: 0.03125 | H11: 0.03125 | I11: 0.03125
A12: Q2P | B12: 0.083333333 | C12: 0.083333333 | D12: 0.083333333 | E12: 0.083333333 | F12: 0.083333333 | G12: 0.083333333 | H12: 0.083333333 | I12: 0.083333333
A13: Q2A | B13: 0.052083333 | C13: 0.052083333 | D13: 0.052083333 | E13: 0.052083333 | F13: 0.052083333 | G13: 0.052083333 | H13: 0.052083333 | I13: 0.052083333
A14: Q3N | B14: 0.098958333 | C14: 0.098958333 | D14: 0.098958333 | E14: 0.098958333 | F14: 0.098958333 | G14: 0.098958333 | H14: 0.098958333 | I14: 0.098958333
A15: Q3M | B15: 0.020833333 | C15: 0.020833333 | D15: 0.020833333 | E15: 0.020833333 | F15: 0.020833333 | G15: 0.020833333 | H15: 0.020833333 | I15: 0.020833333
A16: Q3P | B16: 0.072916667 | C16: 0.072916667 | D16: 0.072916667 | E16: 0.072916667 | F16: 0.072916667 | G16: 0.072916667 | H16: 0.072916667 | I16: 0.072916667
... A21: Q4A | B21: 0.026041667 | C21: 0.026041667 | D21: 0.026041667 | E21: 0.026041667 | F21: 0.026041667 | G21: 0.026041667 | H21: 0.026041667 | I21: 0.026041667

Sheet Par_TagTechnologyToSector
A1: TagTechnologyToSector{t in TECHNOLOGY, se in SECTOR}
A2: Assigns Technologies to the different sectors.
A3: Unit: Binary
A5: Technology | B5: Power | C5: Industry | D5: Buildings | E5: Transportation | F5: Resources | G5: Storages | H5: Transformation | I5: CHP
A6: A_Rooftop_Commercial | F6: 1
A7: A_Rooftop_Residential | F7: 1
A8: D_Battery_Li-Ion | G8: 1
A9: D_Battery_Redox | G9: 1
A10: D_Gas_H2 | G10: 1
A11: D_Heat_HLR | G11: 1
A12: D_Heat_HLI | G12: 1
A13: D_PHS | G13: 1
A14: D_CAES | G14: 1
A15: FRT_Rail_Conv | E15: 1
A16: FRT_Rail_Electric | E16: 1
A17: FRT_Road_BEV | E17: 1
A18: FRT_Road_H2 | E18: 1
A19: FRT_Road_ICE | E19: 1
A20: FRT_Road_PHEV | E20: 1
A21: FRT_Road_OH | E21: 1
A22: FRT_Ship_Bio | E22: 1
A23: FRT_Ship_Conv | E23: 1
A24: P_Biomass | B24: 1
A25: P_Coal_Hardcoal | B25: 1
A26: P_Coal_Lignite | B26: 1
A27: P_Gas | B27: 1
A28: P_Nuclear | B28: 1
A29: P_Oil | B29: 1
A30: PSNG_Air_Bio | E30: 1
A31: PSNG_Air_Conv | E31: 1
A32: PSNG_Air_H2 | E32: 1
A33: PSNG_Rail_Conv | E33: 1
A34: PSNG_Rail_Electric | E34: 1
A35: PSNG_Road_BEV | E35: 1
A36: PSNG_Road_H2 | E36: 1
A37: PSNG_Road_ICE | E37: 1
A38: PSNG_Road_PHEV | E38: 1
A39: R_Coal_Hardcoal | F39: 1
A40: R_Coal_Lignite | F40: 1
A41: R_Gas | F41: 1
...

Sheet Par_CapacityToActivityUnit
A1: CapacityToActivityUnit{r in REGION, t in TECHNOLOGY}
A2: Converts capacity to activity. Here we use a factor of 31.536, which is the level of energy production in PJ produced from 1 GW operating for 1 year (1GW * 8760 * 3600 / 10^6)
A3: Unit: PJ/GW-YR
A5: Region | B5: A_Rooftop_Commercial | C5: A_Rooftop_Residential | D5: D_Battery_Li-Ion | E5: D_Battery_Redox | F5: D_Gas_H2 | G5: D_Gas_Methane | H5: D_Heat_HLR | I5: D_Heat_HLI | J5: D_PHS | K5: D_PHS_Residual | L5: FRT_Rail_Conv | M5: FRT_Rail_Electric | N5: FRT_Road_BEV | O5: FRT_Road_H2 | P5: FRT_Road_ICE | Q5: FRT_Road_PHEV | R5: FRT_Road_OH | S5: FRT_Ship_Bio | T5: FRT_Ship_Conv | U5: P_Biomass | V5: P_Coal_Hardcoal | W5: P_Coal_Lignite | X5: P_Gas | Y5: P_Nuclear | Z5: P_Oil | AA5: PSNG_Air_Bio | AB5: PSNG_Air_Conv | AC5: PSNG_Air_H2 | AD5: PSNG_Rail_Conv | AE5: PSNG_Rail_Electric | AF5: PSNG_Road_BEV | AG5: PSNG_Road_H2 | AH5: PSNG_Road_ICE | AI5: PSNG_Road_PHEV | AJ5: R_Coal_Hardcoal | AK5: R_Coal_Lignite | AL5: R_Gas | AM5: R_Nuclear | AN5: R_Oil | AO5: RES_Biomass | AP5: RES_CSP | AQ5: RES_Geothermal | AR5: RES_Hydro_Large | AS5: RES_Hydro_Small | AT5: RES_Ocean | AU5: RES_PV_Rooftop_Commercial | AV5: RES_PV_Rooftop_Residential | AW5: RES_PV_Utility_Avg | AX5: RES_PV_Utility_Inf | AY5: RES_PV_Utility_Opt | AZ5: RES_Wind_Offshore_Transitional | BA5: RES_Wind_Offshore_Shallow | BB5: RES_Wind_Offshore_Deep | BC5: RES_Wind_Onshore_Avg | BD5: RES_Wind_Onshore_Inf | BE5: RES_Wind_Onshore_Opt | BF5: X_Electrolysis | BG5: X_Fuel_Cell | BH5: X_Methanation | BI5: Z_Import_Hardcoal | BJ5: Z_Import_Gas | BK5: Z_Import_Oil | BL5: HHT_H2 | BM5: D_CAES | BN5: CHP_Biomass_CCS | BO5: P_Biomass_CCS | BP5: A_CCS_Capacity | BQ5: D_Gas_Methane | BR5: HLR_Gas_Boiler | BS5: HLR_Gas_CHP | BT5: HLR_Biomass | BU5: HLR_Biomass_CHP | BV5: HLR_Hardcoal | BW5: HLR_Lignite | BX5: HLR_Hardcoal_CHP | BY5: HLR_Lignite_CHP | BZ5: HLR_Direct_Electric | CA5: HLR_Solar_Thermal | CB5: HLR_Heatpump_Aerial | CC5: HLR_Heatpump_Ground | CD5: HLR_Geothermal | CE5: HLR_Oil_Boiler | CF5: HLI_Gas_Boiler | CG5: HLI_Gas_CHP | CH5: HLI_Biomass | CI5: HLI_Biomass_CHP | CJ5: HLI_Hardcoal | CK5: HLI_Lignite | CL5: HLI_Hardcoal_CHP | CM5: HLI_Direct_Electric | CN5: HLI_Solar_Thermal | CO5: HLI_Fuelcell | CP5: HLI_Geothermal | CQ5: HLI_Oil_Boiler | CR5: HLI_Oil_CHP | CS5: HMI_Gas | CT5: HMI_Biomass | CU5: HMI_HardCoal | CV5: HMI_Steam_Electric | CW5: HMI_Oil | CX5: HHI_BF_BOF | CY5: HHI_DRI_EAF | CZ5: HHI_Scrap_EAF | DA5: HHI_H2DRI_EAF | DB5: HHI_Molten_Electrolysis | DC5: HHI_Bio_BF_BOF | DD5: HLI_Lignite_CHP | DE5: HHI_BF_BOF_CCS | DF5: HHI_DRI_EAF_CCS | DG5: HLI_Biomass_CHP_CCS | DH5: HLI_Hardcoal_CHP_CCS | DI5: HLI_Lignite_CHP_CCS | DJ5: HLR_Biomass_CHP_CCS | DK5: HLR_Hardcoal_CHP_CCS | DL5: HLR_Lignite_CHP_CCS | DM5: HMI_Gas_CCS | DN5: HMI_HardCoal_CCS | DO5: P_Coal_Hardcoal_CCS | DP5: P_Coal_Lignite_CCS | DQ5: P_Gas_CCS | DR5: X_SMR | DS5: X_SMR_CCS | DT5: X_DAC | DU5: A_Air | DV5: HLR_H2_Boiler | DW5: HLI_H2_Boiler | DX5: X_Biofuel | DY5: HMI_H2 | DZ5: X_Powerfuel | EA5: RES_Grass | EB5: RES_Wood | EC5: RES_Residues | ED5: RES_Paper_Cardboard | EE5: RES_Roundwood | EF5: RES_Biogas | EG5: X_Gasifier | EH5: X_Liquifier | EI5: FRT_Road_LNG | EJ5: FRT_Ship_LNG | EK5: PSNG_Road_LNG | EL5: P_H2_OCGT | EM5: A_Air | EN5: X_DAC_LT | EO5: X_DAC_HT | EP5: Z_Import_H2 | EQ5: Z_ETS_Buy | ER5: Z_ETS_Sell | ES5: CHP_Biomass_Solid | ET5: CHP_Coal_Hardcoal | EU5: CHP_Coal_Lignite | EV5: CHP_Gas_CCGT_Natural | EW5: CHP_Gas_CCGT_Biogas | EX5: CHP_Gas_CCGT_SynGas | EY5: CHP_Hydrogen_FuelCell | EZ5: CHP_Biomass_Solid_CCS | FA5: CHP_Coal_Hardcoal_CCS | FB5: CHP_Coal_Lignite_CCS | FC5: CHP_Gas_CCGT_Natural_CCS | FD5: CHP_Gas_CCGT_Biogas_CCS | FE5: HLI_Convert_DH | FF5: HLR_Convert_DH | FG5: CHP_Oil | FH5: P_Gas_CCGT | FI5: P_Gas_OCGT | FJ5: P_Gas_Engines | FK5: Res_PV_Utility_Tracking
A6: DE | B6: 1 | C6: 1 | D6: 31.536 | E6: 31.536 | F6: 31.536 | G6: 31.536 | H6: 31.536 | I6: 31.536 | J6: 31.536 | K6: 31.536 | L6: 1 | M6: 1 | N6: 1 | O6: 1 | P6: 1 | Q6: 1 | R6: 1 | S6: 1 | T6: 1 | U6: 31.536 | V6: 31.536 | W6: 31.536 | X6: 31.536 | Y6: 31.536 | Z6: 31.536 | AA6: 1 | AB6: 1 | AC6: 1 | AD6: 1 | AE6: 1 | AF6: 1 | AG6: 1 | AH6: 1 | AI6: 1 | AJ6: 31.536 | AK6: 31.536 | AL6: 31.536 | AM6: 31.536 | AN6: 31.536 | AO6: 0 | AP6: 31.536 | AQ6: 31.536 | AR6: 31.536 | AS6: 31.536 | AT6: 31.536 | AU6: 31.536 | AV6: 31.536 | AW6: 31.536 | AX6: 31.536 | AY6: 31.536 | AZ6: 31.536 | BA6: 31.536 | BB6: 31.536 | BC6: 31.536 | BD6: 31.536 | BE6: 31.536 | BF6: 31.536 | BG6: 31.536 | BH6: 31.536 | BI6: 31.536 | BJ6: 31.536 | BK6: 31.536 | BL6: 31.536 | BM6: 31.536 | BN6: 31.536 | BO6: 31.536 | BP6: 1 | BQ6: 1 | BR6: 31.536 | BS6: 31.536 | BT6: 31.536 | BU6: 31.536 | BV6: 31.536 | BW6: 31.536 | BX6: 31.536 | BY6: 31.536 | BZ6: 31.536 | CA6: 31.536 | CB6: 31.536 | CC6: 31.536 | CD6: 31.536 | CE6: 31.536 | CF6: 31.536 | CG6: 31.536 | CH6: 31.536 | CI6: 31.536 | CJ6: 31.536 | CK6: 31.536 | CL6: 31.536 | CM6: 31.536 | CN6: 31.536 | CO6: 31.536 | CP6: 31.536 | CQ6: 31.536 | CR6: 31.536 | CS6: 31.536 | CT6: 31.536 | CU6: 31.536 | CV6: 31.536 | CW6: 31.536 | CX6: 31.536 | CY6: 31.536 | CZ6: 31.536 | DA6: 31.536 | DB6: 31.536 | DC6: 31.536 | DD6: 31.536 | DE6: 31.536 | DF6: 31.536 | DG6: 31.536 | DH6: 31.536 | DI6: 31.536 | DJ6: 31.536 | DK6: 31.536 | DL6: 31.536 | DM6: 31.536 | DN6: 31.536 | DO6: 31.536 | DP6: 31.536 | DQ6: 31.536 | DR6: 31.536 | DS6: 31.536 | DT6: 31.536 | DU6: 1 | DV6: 31.536 | DW6: 31.536 | DX6: 31.536 | DY6: 31.536 | DZ6: 1 | EA6: 1 | EB6: 1 | EC6: 1 | ED6: 1 | EE6: 1 | EF6: 1 | EG6: 31.536 | EH6: 31.536 | EI6: 1 | EJ6: 1 | EK6: 1 | EL6: 31.536 | EM6: 1 | EN6: 1 | EO6: 1 | EP6: 31.536 | EQ6: 1 | ER6: 1 | ES6: 31.536 | ET6: 31.536 | EU6: 31.536 | EV6: 31.536 | EW6: 31.536 | EX6: 31.536 | EY6: 31.536 | EZ6: 31.536 | FA6: 31.536 | FB6: 31.536 | FC6: 31.536 | FD6: 31.536 | FE6: 1 | FF6: 1 | FG6: 31.536 | FH6: 31.536 | FI6: 31.536 | FJ6: 31.536 | FK6: 31.536

Sheet Par_Conversionls
A1: Conversionls{l in TIMESLICE, ls in SEASON}
A2: Set equal to 1 to assign a particular time slice to a season. Set equal to 0 in order not to assign a particular time slice to a season.
A3: Unit: Binary
A5: Timeslice | B5: 1 | C5: 2 | D5: 3 | E5: 4
A6: Q1N | B6: 1
A7: Q1M | B7: 1
A8: Q1P | B8: 1
A9: Q1A | B9: 1
A10: Q2N | C10: 1
A11: Q2M | C11: 1
A12: Q2P | C12: 1
A13: Q2A | C13: 1
A14: Q3N | D14: 1
A15: Q3M | D15: 1
A16: Q3P | D16: 1
A17: Q3A | D17: 1
A18: Q4N | E18: 1
A19: Q4M | E19: 1
A20: Q4P | E20: 1
A21: Q4A | E21: 1

Sheet Par_Conversionld
A1: Conversionld{l in TIMESLICE, ld in DAYTYPE}
A2: Set equal to 1 to assign a particular time slice to a day type. Set equal to 0 in order not to assign a particular time slice to a day type.
A3: Unit: Binary
A5: Timeslice | B5: 1
A6: Q1N | B6: 1
A7: Q1M | B7: 1
A8: Q1P | B8: 1
A9: Q1A | B9: 1
A10: Q2N | B10: 1
A11: Q2M | B11: 1
A12: Q2P | B12: 1
A13: Q2A | B13: 1
A14: Q3N | B14: 1
A15: Q3M | B15: 1
A16: Q3P | B16: 1
... A21: Q4A | B21: 1

Sheet Par_Conversionlh
A1: Conversionlh{l in TIMESLICE, lh in DAILYTIMEBRACKET}
A2: Set equal to 1 to assign a particular time slice to a daily time bracket. Set equal to 0 in order not to assign a particular time slice to a daily time bracket.
A3: Unit: Binary
B4: N | C4: M | D4: P | E4: A
A5: Timeslice | B5: 4 | C5: 1 | D5: 2 | E5: 3
A6: Q1N | B6: 1
A7: Q1M | C7: 1
A8: Q1P | D8: 1
A9: Q1A | E9: 1
A10: Q2N | B10: 1
A11: Q2M | C11: 1
A12: Q2P | D12: 1
A13: Q2A | E13: 1
A14: Q3N | B14: 1
A15: Q3M | C15: 1
A16: Q3P | D16: 1
A17: Q3A | E17: 1
A18: Q4N | B18: 1
A19: Q4M | C19: 1
A20: Q4P | D20: 1
A21: Q4A | E21: 1

Sheet Par_TradeRoute
A1: TradeRoute{f in FUEL, r in REGION1, rr in REGION2}
A2: Defines trade links between regions for specific fuels. If r is linked to rr, rr has also to be linked with r. Symmetrical matrix with diagonal of zeroes
A3: Unit: km
C5: FR | D5: AT | E5: BE | F5: BG | G5: CH | H5: CZ | I5: DE | J5: DK | K5: EE | L5: ES | M5: FI | N5: GR | O5: HR | P5: HU | Q5: IE | R5: IT | S5: LT | T5: LU | U5: LV | V5: NONEU_Balkan | W5: NL | X5: NO | Y5: PL | Z5: PT | AA5: RO | AB5: SE | AC5: SI | AD5: SK | AE5: UK | AF5: TR
A6: Biofuel | B6: AT | C6: 1462.5 | D6: 0 | E6: 770.24 | F6: 1022.45 | G6: 456.36 | H6: 254.84 | I6: 477.04 | J6: 973.03 | K6: 0 | L6: 1640.58 | M6: 0 | N6: 1188.01 | O6: 332.27 | P6: 400.59 | Q6: 0 | R6: 557.69 | S6: 1094.84 | T6: 640.32 | U6: 1264.26 | V6: 667.29 | W6: 804.24 | X6: 0 | Y6: 630.36 | Z6: 0 | AA6: 850.72 | AB6: 1698.79 | AC6: 171.24 | AD6: 416.67 | AE6: 1399.02 | AF6: 0
A7: Biofuel | B7: BE | C7: 300 | D7: 770.24 | E7: 0 | F7: 0 | G7: 501.4 | H7: 767.87 | I7: 406.5 | J7: 692.16 | K7: 0 | L7: 1325.38 | M7: 0 | N7: 0 | O7: 1075.07 | P7: 1146.05 | Q7: 924.14 | R7: 1040.22 | S7: 0 | T7: 140.4 | U7: 0 | V7: 0 | W7: 192.2 | X7: 1636.14 | Y7: 1037.53 | Z7: 0 | AA7: 0 | AB7: 1535.26 | AC7: 903.98 | AD7: 1089.56 | AE7: 645.59 | AF7: 0
A8: Biofuel | B8: BG | C8: 0 | D8: 1022.45 | E8: 0 | F8: 0 | G8: 1415.45 | H8: 1087.05 | I8: 1458.02 | J8: 0 | K8: 0 | L8: 0 | M8: 0 | N8: 453.95 | O8: 753.16 | P8: 671.18 | Q8: 0 | R8: 1075.51 | S8: 0 | T8: 0 | U8: 0 | V8: 489.51 | W8: 0 | X8: 0 | Y8: 1129.69 | Z8: 0 | AA8: 343.03 | AB8: 0 | AC8: 908.29 | AD8: 797.9 | AE8: 0 | AF8: 428
A9: Biofuel | B9: CH | C9: 350 | D9: 456.36 | E9: 501.4 | F9: 1415.45 | G9: 0 | H9: 619.89 | I9: 504.62 | J9: 1027.05 | K9: 0 | L9: 1204.01 | M9: 0 | N9: 0 | O9: 662.94 | P9: 850.87 | Q9: 0 | R9: 540.01 | S9: 0 | T9: 367.02 | U9: 0 | V9: 978.2 | W9: 637.55 | X9: 0 | Y9: 1001.53 | Z9: 0 | AA9: 1292.28 | AB9: 1857.41 | AC9: 511.84 | AD9: 869.38 | AE9: 1134.76 | AF9: 0
A10: Biofuel | B10: CZ | C10: 1630.33 | D10: 254.84 | E10: 767.87 | F10: 1087.05 | G10: 619.89 | H10: 0 | I10: 382.63 | J10: 777.76 | K10: 1194.05 | L10: 0 | M10: 0 | N10: 1334.1 | O10: 528.63 | P10: 415.87 | Q10: 0 | R10: 812.43 | S10: 850.9 | T10: 665.24 | U10: 1016.04 | V10: 829.38 | W10: 738.71 | X10: 1642 | Y10: 390.18 | Z10: 0 | AA10: 842.37 | AB10: 1454.22 | AC10: 404.31 | AD10: 323.69 | AE10: 1341.38 | AF10: 0
A11: Biofuel | B11: DE | C11: 500 | D11: 477.04 | E11: 406.5 | F11: 1458.02 | G11: 504.62 | H11: 382.63 | I11: 0 | J11: 540.49 | K11: 1281.04 | L11: 1624.96 | M11: 1750.79 | N11: 1662.66 | O11: 809.27 | P11: 790.13 | Q11: 1286.09 | R11: 934.15 | S11: 1015.33 | T11: 339.26 | U11: 1144.6 | V11: 1143.09 | W11: 356.15 | X11: 1503.63 | Y11: 633.87 | Z11: 0 | AA11: 1224.85 | AB11: 1354.27 | AC11: 643.65 | AD11: 705.3 | AE11: 959.53 | AF11: 0
A12: Biofuel | B12: DK | C12: 1789.51 | D12: 973.03 | E12: 692.16 | F12: 0 | G12: 1027.05 | H12: 777.76 | I12: 540.49 | J12: 0 | K12: 978.44 | L12: 0 | M12: 1298.09 | N12: 0 | O12: 1294.23 | P12: 1171.94 | Q12: 1213.43 | R12: 1472.56 | S12: 873.01 | T12: 737.81 | U12: 921.65 | V12: 0 | W12: 503.89 | X12: 700 | Y12: 745.5 | Z12: 0 | AA12: 1533.41 | AB12: 400 | AC12: 1144.12 | AD12: 1030.02 | AE12: 850.09 | AF12: 0
A13: Biofuel | B13: EE | C13: 0 | D13: 0 | E13: 0 | F13: 0 | G13: 0 | H13: 1194.05 | I13: 1281.04 | J13: 978.44 | K13: 0 | L13: 0 | M13: 647.91 | N13: 0 | O13: 0 | P13: 0 | Q13: 0 | R13: 0 | S13: 384.47 | T13: 0 | U13: 205.65 | V13: 0 | W13: 0 | X13: 885 | Y13: 825.43 | Z13: 0 | AA13: 0 | AB13: 661.72 | AC13: 0 | AD13: 1177.79 | AE13: 0 | AF13: 0
A14: Biofuel | B14: ES | C14: 229.59 | D14: 1640.58 | E14: 1325.38 | F14: 0 | G14: 1204.01 | H14: 0 | I14: 1624.96 | J14: 0 | K14: 0 | L14: 0 | M14: 0 | N14: 0 | O14: 1723.59 | P14: 0 | Q14: 1479.45 | R14: 1341.02 | S14: 0 | T14: 1307.36 | U14: 0 | V14: 0 | W14: 1513.18 | X14: 0 | Y14: 0 | Z14: 421.67 | AA14: 0 | AB14: 0 | AC14: 1632.96 | AD14: 0 | AE14: 1549.51 | AF14: 0
A15: Biofuel | B15: FI | C15: 0 | D15: 0 | E15: 0 | F15: 0 | G15: 0 | H15: 0 | I15: 1750.79 | J15: 1298.09 | K15: 647.91 | L15: 0 | M15: 0 | N15: 0 | O15: 0 | P15: 0 | Q15: 0 | R15: 0 | S15: 1026.31 | T15: 0 | U15: 852.16 | V15: 0 | W15: 0 | X15: 1000 | Y15: 1430.78 | Z15: 0 | AA15: 0 | AB15: 505.83 | AC15: 0 | AD15: 0 | AE15: 0 | AF15: 0
A16: Biofuel | B16: FR | C16: 0 | D16: 1462.5 | E16: 300 | F16: 0 | G16: 350 | H16: 1630.33 | I16: 500 | J16: 1789.51 | K16: 0 | L16: 229.59 | M16: 0 | N16: 2201.09 | O16: 1577.99 | P16: 1838.39 | Q16: 1284.49 | R16: 1000 | S16: 0 | T16: 1087.05 | U16: 0 | V16: 1809.09 | W16: 1285.66 | X16: 2702.36 | Y16: 2000.6 | Z16: 560.61 | AA16: 2252.62 | AB16: 2623.55 | AC16: 1472.14 | AD16: 1879.08 | AE16: 600 | AF16: 0
A17: Biofuel | B17: GR | C17: 2201.09 | D17: 1188.01 | E17: 0 | F17: 453.95 | G17: 0 | H17: 1334.1 | I17: 1662.66 | J17: 0 | K17: 0 | L17: 0 | M17: 0 | N17: 0 | O17: 859.98 | P17: 947.65 | Q17: 0 | R17: 1007.1 | S17: 0 | T17: 0 | U17: 0 | V17: 521.16 | W17: 0 | X17: 0 | Y17: 1480.09 | Z17: 0 | AA17: 772.6 | AB17: 0 | AC17: 1031.62 | AD17: 1109.61 | AE17: 0 | AF17: 868
... A455: ETS | B455: TR | C455: 1 | D455: 1 | E455: 1 | F455: 1 | G455: 1 | H455: 1 | I455: 1 | J455: 1 | K455: 1 | L455: 1 | M455: 1 | N455: 1 | O455: 1 | P455: 1 | Q455: 1 | R455: 1 | S455: 1 | T455: 1 | U455: 1 | V455: 1 | W455: 1 | X455: 1 | Y455: 1 | Z455: 1 | AA455: 1 | AB455: 1 | AC455: 1 | AD455: 1 | AE455: 1 | AF455: 0

Sheet Par_TradeCosts
A1: TradeCosts{f in FUEL, r in REGION1, rr in REGION2}
A2: Costs for trading a fuel from one region to another.
A3: Unit: M€/PJ
C5: FR | D5: AT | E5: BE | F5: BG | G5: CH | H5: CZ | I5: DE | J5: DK | K5: EE | L5: ES | M5: FI | N5: GR | O5: HR | P5: HU | Q5: IE | R5: IT | S5: LT | T5: LU | U5: LV | V5: NONEU_Balkan | W5: NL | X5: NO | Y5: PL | Z5: PT | AA5: RO | AB5: SE | AC5: SI | AD5: SK | AE5: UK | AF5: TR
A6: Distance | B6: AT | C6: =Par_TradeRoute!C6 -> 1462.5 | D6: =Par_TradeRoute!D6 -> 0 | E6: =Par_TradeRoute!E6 -> 770.24 | F6: =Par_TradeRoute!F6 -> 1022.45 | G6: =Par_TradeRoute!G6 -> 456.36 | H6: =Par_TradeRoute!H6 -> 254.84 | I6: =Par_TradeRoute!I6 -> 477.04 | J6: =Par_TradeRoute!J6 -> 973.03 | ... AF6: =Par_TradeRoute!AF6 -> 0
A7: Distance | B7: BE | C7: =Par_TradeRoute!C7 -> 300 | D7: =Par_TradeRoute!D7 -> 770.24 | E7: =Par_TradeRoute!E7 -> 0 | F7: =Par_TradeRoute!F7 -> 0 | G7: =Par_TradeRoute!G7 -> 501.4 | H7: =Par_TradeRoute!H7 -> 767.87 | I7: =Par_TradeRoute!I7 -> 406.5 | J7: =Par_TradeRoute!J7 -> 692.16 | ... AF7: =Par_TradeRoute!AF7 -> 0
A8: Distance | B8: BG | C8: =Par_TradeRoute!C8 -> 0 | D8: =Par_TradeRoute!D8 -> 1022.45 | E8: =Par_TradeRoute!E8 -> 0 | F8: =Par_TradeRoute!F8 -> 0 | G8: =Par_TradeRoute!G8 -> 1415.45 | H8: =Par_TradeRoute!H8 -> 1087.05 | I8: =Par_TradeRoute!I8 -> 1458.02 | J8: =Par_TradeRoute!J8 -> 0 | ... AF8: =Par_TradeRoute!AF8 -> 428
A9: Distance | B9: CH | C9: =Par_TradeRoute!C9 -> 350 | D9: =Par_TradeRoute!D9 -> 456.36 | E9: =Par_TradeRoute!E9 -> 501.4 | F9: =Par_TradeRoute!F9 -> 1415.45 | G9: =Par_TradeRoute!G9 -> 0 | H9: =Par_TradeRoute!H9 -> 619.89 | I9: =Par_TradeRoute!I9 -> 504.62 | J9: =Par_TradeRoute!J9 -> 1027.05 | ... AF9: =Par_TradeRoute!AF9 -> 0
A10: Distance | B10: CZ | C10: =Par_TradeRoute!C10 -> 1630.33 | D10: =Par_TradeRoute!D10 -> 254.84 | E10: =Par_TradeRoute!E10 -> 767.87 | F10: =Par_TradeRoute!F10 -> 1087.05 | G10: =Par_TradeRoute!G10 -> 619.89 | H10: =Par_TradeRoute!H10 -> 0 | I10: =Par_TradeRoute!I10 -> 382.63 | J10: =Par_TradeRoute!J10 -> 777.76 | ... AF10: =Par_TradeRoute!AF10 -> 0
A11: Distance | B11: DE | C11: =Par_TradeRoute!C11 -> 500 | D11: =Par_TradeRoute!D11 -> 477.04 | E11: =Par_TradeRoute!E11 -> 406.5 | F11: =Par_TradeRoute!F11 -> 1458.02 | G11: =Par_TradeRoute!G11 -> 504.62 | H11: =Par_TradeRoute!H11 -> 382.63 | I11: =Par_TradeRoute!I11 -> 0 | J11: =Par_TradeRoute!J11 -> 540.49 | ... AF11: =Par_TradeRoute!AF11 -> 0
A12: Distance | B12: DK | C12: =Par_TradeRoute!C12 -> 1789.51 | D12: =Par_TradeRoute!D12 -> 973.03 | E12: =Par_TradeRoute!E12 -> 692.16 | F12: =Par_TradeRoute!F12 -> 0 | G12: =Par_TradeRoute!G12 -> 1027.05 | H12: =Par_TradeRoute!H12 -> 777.76 | I12: =Par_TradeRoute!I12 -> 540.49 | J12: =Par_TradeRoute!J12 -> 0 | ... AF12: =Par_TradeRoute!AF12 -> 0
A13: Distance | B13: EE | C13: =Par_TradeRoute!C13 -> 0 | D13: =Par_TradeRoute!D13 -> 0 | E13: =Par_TradeRoute!E13 -> 0 | F13: =Par_TradeRoute!F13 -> 0 | G13: =Par_TradeRoute!G13 -> 0 | H13: =Par_TradeRoute!H13 -> 1194.05 | I13: =Par_TradeRoute!I13 -> 1281.04 | J13: =Par_TradeRoute!J13 -> 978.44 | ... AF13: =Par_TradeRoute!AF13 -> 0
A14: Distance | B14: ES | C14: =Par_TradeRoute!C14 -> 229.59 | D14: =Par_TradeRoute!D14 -> 1640.58 | E14: =Par_TradeRoute!E14 -> 1325.38 | F14: =Par_TradeRoute!F14 -> 0 | G14: =Par_TradeRoute!G14 -> 1204.01 | H14: =Par_TradeRoute!H14 -> 0 | I14: =Par_TradeRoute!I14 -> 1624.96 | J14: =Par_TradeRoute!J14 -> 0 | ... AF14: =Par_TradeRoute!AF14 -> 0
A15: Distance | B15: FI | C15: =Par_TradeRoute!C15 -> 0 | D15: =Par_TradeRoute!D15 -> 0 | E15: =Par_TradeRoute!E15 -> 0 | F15: =Par_TradeRoute!F15 -> 0 | G15: =Par_TradeRoute!G15 -> 0 | H15: =Par_TradeRoute!H15 -> 0 | I15: =Par_TradeRoute!I15 -> 1750.79 | J15: =Par_TradeRoute!J15 -> 1298.09 | ... AF15: =Par_TradeRoute!AF15 -> 0
A16: Distance | B16: FR | C16: =Par_TradeRoute!C16 -> 0 | D16: =Par_TradeRoute!D16 -> 1462.5 | E16: =Par_TradeRoute!E16 -> 300 | F16: =Par_TradeRoute!F16 -> 0 | G16: =Par_TradeRoute!G16 -> 350 | H16: =Par_TradeRoute!H16 -> 1630.33 | I16: =Par_TradeRoute!I16 -> 500 | J16: =Par_TradeRoute!J16 -> 1789.51 | ... AF16: =Par_TradeRoute!AF16 -> 0
A17: Distance | B17: GR | C17: =Par_TradeRoute!C17 -> 2201.09 | D17: =Par_TradeRoute!D17 -> 1188.01 | E17: =Par_TradeRoute!E17 -> 0 | F17: =Par_TradeRoute!F17 -> 453.95 | G17: =Par_TradeRoute!G17 -> 0 | H17: =Par_TradeRoute!H17 -> 1334.1 | I17: =Par_TradeRoute!I17 -> 1662.66 | J17: =Par_TradeRoute!J17 -> 0 | ... AF17: =Par_TradeRoute!AF17 -> 868
... A35: Distance | B35: UK | C35: =Par_TradeRoute!C35 -> 600 | D35: =Par_TradeRoute!D35 -> 1399.02 | E35: =Par_TradeRoute!E35 -> 645.59 | F35: =Par_TradeRoute!F35 -> 0 | G35: =Par_TradeRoute!G35 -> 1134.76 | H35: =Par_TradeRoute!H35 -> 1341.38 | I35: =Par_TradeRoute!I35 -> 959.53 | J35: =Par_TradeRoute!J35 -> 850.09 | ... AF35: =Par_TradeRoute!AF35 -> 0
A36: Hardcoal | B36: AT | C36: =ROUND(IF(C6>0, ((0.0014*C6+13.97)/1.15)*(10^12)/(1000*29308)/1000000, 0),3) -> 0.475 | D36: =ROUND(IF(D6>0, ((0.0014*D6+13.97)/1.15)*(10^12)/(1000*29308)/1000000, 0),3) -> 0 | E36: =ROUND(IF(E6>0, ((0.0014*E6+13.97)/1.15)*(10^12)/(1000*29308)/1000000, 0),3) -> 0.446 | F36: =ROUND(IF(F6>0, ((0.0014*F6+13.97)/1.15)*(10^12)/(1000*29308)/1000000, 0),3) -> 0.457 | G36: =ROUND(IF(G6>0, ((0.0014*G6+13.97)/1.15)*(10^12)/(1000*29308)/1000000, 0),3) -> 0.433 | H36: =ROUND(IF(H6>0, ((0.0014*H6+13.97)/1.15)*(10^12)/(1000*29308)/1000000, 0),3) -> 0.425 | I36: =ROUND(IF(I6>0, ((0.0014*I6+13.97)/1.15)*(10^12)/(1000*29308)/1000000, 0),3) -> 0.434 | J36: =ROUND(IF(J6>0, ((0.0014*J6+13.97)/1.15)*(10^12)/(1000*29308)/1000000, 0),3) -> 0.455 | ... AF36: =ROUND(IF(AF6>0, ((0.0014*AF6+13.97)/1.15)*(10^12)/(1000*29308)/1000000, 0),3) -> 0
A37: Hardcoal | B37: BE | C37: =ROUND(IF(C7>0, ((0.0014*C7+13.97)/1.15)*(10^12)/(1000*29308)/1000000, 0),3) -> 0.427 | D37: =ROUND(IF(D7>0, ((0.0014*D7+13.97)/1.15)*(10^12)/(1000*29308)/1000000, 0),3) -> 0.446 | E37: =ROUND(IF(E7>0, ((0.0014*E7+13.97)/1.15)*(10^12)/(1000*29308)/1000000, 0),3) -> 0 | F37: =ROUND(IF(F7>0, ((0.0014*F7+13.97)/1.15)*(10^12)/(1000*29308)/1000000, 0),3) -> 0 | G37: =ROUND(IF(G7>0, ((0.0014*G7+13.97)/1.15)*(10^12)/(1000*29308)/1000000, 0),3) -> 0.435 | H37: =ROUND(IF(H7>0, ((0.0014*H7+13.97)/1.15)*(10^12)/(1000*29308)/1000000, 0),3) -> 0.446 | I37: =ROUND(IF(I7>0, ((0.0014*I7+13.97)/1.15)*(10^12)/(1000*29308)/1000000, 0),3) -> 0.431 | J37: =ROUND(IF(J7>0, ((0.0014*J7+13.97)/1.15)*(10^12)/(1000*29308)/1000000, 0),3) -> 0.443 | ... AF37: =ROUND(IF(AF7>0, ((0.0014*AF7+13.97)/1.15)*(10^12)/(1000*29308)/1000000, 0),3) -> 0
A38: Hardcoal | B38: BG | C38: =ROUND(IF(C8>0, ((0.0014*C8+13.97)/1.15)*(10^12)/(1000*29308)/1000000, 0),3) -> 0 | D38: =ROUND(IF(D8>0, ((0.0014*D8+13.97)/1.15)*(10^12)/(1000*29308)/1000000, 0),3) -> 0.457 | E38: =ROUND(IF(E8>0, ((0.0014*E8+13.97)/1.15)*(10^12)/(1000*29308)/1000000, 0),3) -> 0 | F38: =ROUND(IF(F8>0, ((0.0014*F8+13.97)/1.15)*(10^12)/(1000*29308)/1000000, 0),3) -> 0 | G38: =ROUND(IF(G8>0, ((0.0014*G8+13.97)/1.15)*(10^12)/(1000*29308)/1000000, 0),3) -> 0.473 | H38: =ROUND(IF(H8>0, ((0.0014*H8+13.97)/1.15)*(10^12)/(1000*29308)/1000000, 0),3) -> 0.46 | I38: =ROUND(IF(I8>0, ((0.0014*I8+13.97)/1.15)*(10^12)/(1000*29308)/1000000, 0),3) -> 0.475 | J38: =ROUND(IF(J8>0, ((0.0014*J8+13.97)/1.15)*(10^12)/(1000*29308)/1000000, 0),3) -> 0 | ... AF38: =ROUND(IF(AF8>0, ((0.0014*AF8+13.97)/1.15)*(10^12)/(1000*29308)/1000000, 0),3) -> 0.432
A39: Hardcoal | B39: CH | C39: =ROUND(IF(C9>0, ((0.0014*C9+13.97)/1.15)*(10^12)/(1000*29308)/1000000, 0),3) -> 0.429 | D39: =ROUND(IF(D9>0, ((0.0014*D9+13.97)/1.15)*(10^12)/(1000*29308)/1000000, 0),3) -> 0.433 | E39: =ROUND(IF(E9>0, ((0.0014*E9+13.97)/1.15)*(10^12)/(1000*29308)/1000000, 0),3) -> 0.435 | F39: =ROUND(IF(F9>0, ((0.0014*F9+13.97)/1.15)*(10^12)/(1000*29308)/1000000, 0),3) -> 0.473 | G39: =ROUND(IF(G9>0, ((0.0014*G9+13.97)/1.15)*(10^12)/(1000*29308)/1000000, 0),3) -> 0 | H39: =ROUND(IF(H9>0, ((0.0014*H9+13.97)/1.15)*(10^12)/(1000*29308)/1000000, 0),3) -> 0.44 | I39: =ROUND(IF(I9>0, ((0.0014*I9+13.97)/1.15)*(10^12)/(1000*29308)/1000000, 0),3) -> 0.435 | J39: =ROUND(IF(J9>0, ((0.0014*J9+13.97)/1.15)*(10^12)/(1000*29308)/1000000, 0),3) -> 0.457 | ... AF39: =ROUND(IF(AF9>0, ((0.0014*AF9+13.97)/1.15)*(10^12)/(1000*29308)/1000000, 0),3) -> 0
A40: Hardcoal | B40: CZ | C40: =ROUND(IF(C10>0, ((0.0014*C10+13.97)/1.15)*(10^12)/(1000*29308)/1000000, 0),3) -> 0.482 | D40: =ROUND(IF(D10>0, ((0.0014*D10+13.97)/1.15)*(10^12)/(1000*29308)/1000000, 0),3) -> 0.425 | E40: =ROUND(IF(E10>0, ((0.0014*E10+13.97)/1.15)*(10^12)/(1000*29308)/1000000, 0),3) -> 0.446 | F40: =ROUND(IF(F10>0, ((0.0014*F10+13.97)/1.15)*(10^12)/(1000*29308)/1000000, 0),3) -> 0.46 | G40: =ROUND(IF(G10>0, ((0.0014*G10+13.97)/1.15)*(10^12)/(1000*29308)/1000000, 0),3) -> 0.44 | H40: =ROUND(IF(H10>0, ((0.0014*H10+13.97)/1.15)*(10^12)/(1000*29308)/1000000, 0),3) -> 0 | I40: =ROUND(IF(I10>0, ((0.0014*I10+13.97)/1.15)*(10^12)/(1000*29308)/1000000, 0),3) -> 0.43 | J40: =ROUND(IF(J10>0, ((0.0014*J10+13.97)/1.15)*(10^12)/(1000*29308)/1000000, 0),3) -> 0.447 | ... AF40: =ROUND(IF(AF10>0, ((0.0014*AF10+13.97)/1.15)*(10^12)/(1000*29308)/1000000, 0),3) -> 0
A41: Hardcoal | B41: DE | C41: =ROUND(IF(C11>0, ((0.0014*C11+13.97)/1.15)*(10^12)/(1000*29308)/1000000, 0),3) -> 0.435 | D41: =ROUND(IF(D11>0, ((0.0014*D11+13.97)/1.15)*(10^12)/(1000*29308)/1000000, 0),3) -> 0.434 | E41: =ROUND(IF(E11>0, ((0.0014*E11+13.97)/1.15)*(10^12)/(1000*29308)/1000000, 0),3) -> 0.431 | F41: =ROUND(IF(F11>0, ((0.0014*F11+13.97)/1.15)*(10^12)/(1000*29308)/1000000, 0),3) -> 0.475 | G41: =ROUND(IF(G11>0, ((0.0014*G11+13.97)/1.15)*(10^12)/(1000*29308)/1000000, 0),3) -> 0.435 | H41: =ROUND(IF(H11>0, ((0.0014*H11+13.97)/1.15)*(10^12)/(1000*29308)/1000000, 0),3) -> 0.43 | I41: =ROUND(IF(I11>0, ((0.0014*I11+13.97)/1.15)*(10^12)/(1000*29308)/1000000, 0),3) -> 0 | J41: =ROUND(IF(J11>0, ((0.0014*J11+13.97)/1.15)*(10^12)/(1000*29308)/1000000, 0),3) -> 0.437 | ... AF41: =ROUND(IF(AF11>0, ((0.0014*AF11+13.97)/1.15)*(10^12)/(1000*29308)/1000000, 0),3) -> 0
A42: Hardcoal | B42: DK | C42: =ROUND(IF(C12>0, ((0.0014*C12+13.97)/1.15)*(10^12)/(1000*29308)/1000000, 0),3) -> 0.489 | D42: =ROUND(IF(D12>0, ((0.0014*D12+13.97)/1.15)*(10^12)/(1000*29308)/1000000, 0),3) -> 0.455 | E42: =ROUND(IF(E12>0, ((0.0014*E12+13.97)/1.15)*(10^12)/(1000*29308)/1000000, 0),3) -> 0.443 | F42: =ROUND(IF(F12>0, ((0.0014*F12+13.97)/1.15)*(10^12)/(1000*29308)/1000000, 0),3) -> 0 | G42: =ROUND(IF(G12>0, ((0.0014*G12+13.97)/1.15)*(10^12)/(1000*29308)/1000000, 0),3) -> 0.457 | H42: =ROUND(IF(H12>0, ((0.0014*H12+13.97)/1.15)*(10^12)/(1000*29308)/1000000, 0),3) -> 0.447 | I42: =ROUND(IF(I12>0, ((0.0014*I12+13.97)/1.15)*(10^12)/(1000*29308)/1000000, 0),3) -> 0.437 | J42: =ROUND(IF(J12>0, ((0.0014*J12+13.97)/1.15)*(10^12)/(1000*29308)/1000000, 0),3) -> 0 | ... AF42: =ROUND(IF(AF12>0, ((0.0014*AF12+13.97)/1.15)*(10^12)/(1000*29308)/1000000, 0),3) -> 0
A43: Hardcoal | B43: EE | C43: =ROUND(IF(C13>0, ((0.0014*C13+13.97)/1.15)*(10^12)/(1000*29308)/1000000, 0),3) -> 0 | D43: =ROUND(IF(D13>0, ((0.0014*D13+13.97)/1.15)*(10^12)/(1000*29308)/1000000, 0),3) -> 0 | E43: =ROUND(IF(E13>0, ((0.0014*E13+13.97)/1.15)*(10^12)/(1000*29308)/1000000, 0),3) -> 0 | F43: =ROUND(IF(F13>0, ((0.0014*F13+13.97)/1.15)*(10^12)/(1000*29308)/1000000, 0),3) -> 0 | G43: =ROUND(IF(G13>0, ((0.0014*G13+13.97)/1.15)*(10^12)/(1000*29308)/1000000, 0),3) -> 0 | H43: =ROUND(IF(H13>0, ((0.0014*H13+13.97)/1.15)*(10^12)/(1000*29308)/1000000, 0),3) -> 0.464 | I43: =ROUND(IF(I13>0, ((0.0014*I13+13.97)/1.15)*(10^12)/(1000*29308)/1000000, 0),3) -> 0.468 | J43: =ROUND(IF(J13>0, ((0.0014*J13+13.97)/1.15)*(10^12)/(1000*29308)/1000000, 0),3) -> 0.455 | ... AF43: =ROUND(IF(AF13>0, ((0.0014*AF13+13.97)/1.15)*(10^12)/(1000*29308)/1000000, 0),3) -> 0
A44: Hardcoal | B44: ES | C44: =ROUND(IF(C14>0, ((0.0014*C14+13.97)/1.15)*(10^12)/(1000*29308)/1000000, 0),3) -> 0.424 | D44: =ROUND(IF(D14>0, ((0.0014*D14+13.97)/1.15)*(10^12)/(1000*29308)/1000000, 0),3) -> 0.483 | E44: =ROUND(IF(E14>0, ((0.0014*E14+13.97)/1.15)*(10^12)/(1000*29308)/1000000, 0),3) -> 0.47 | F44: =ROUND(IF(F14>0, ((0.0014*F14+13.97)/1.15)*(10^12)/(1000*29308)/1000000, 0),3) -> 0 | G44: =ROUND(IF(G14>0, ((0.0014*G14+13.97)/1.15)*(10^12)/(1000*29308)/1000000, 0),3) -> 0.465 | H44: =ROUND(IF(H14>0, ((0.0014*H14+13.97)/1.15)*(10^12)/(1000*29308)/1000000, 0),3) -> 0 | I44: =ROUND(IF(I14>0, ((0.0014*I14+13.97)/1.15)*(10^12)/(1000*29308)/1000000, 0),3) -> 0.482 | J44: =ROUND(IF(J14>0, ((0.0014*J14+13.97)/1.15)*(10^12)/(1000*29308)/1000000, 0),3) -> 0 | ... AF44: =ROUND(IF(AF14>0, ((0.0014*AF14+13.97)/1.15)*(10^12)/(1000*29308)/1000000, 0),3) -> 0
A45: Hardcoal | B45: FI | C45: =ROUND(IF(C15>0, ((0.0014*C15+13.97)/1.15)*(10^12)/(1000*29308)/1000000, 0),3) -> 0 | D45: =ROUND(IF(D15>0, ((0.0014*D15+13.97)/1.15)*(10^12)/(1000*29308)/1000000, 0),3) -> 0 | E45: =ROUND(IF(E15>0, ((0.0014*E15+13.97)/1.15)*(10^12)/(1000*29308)/1000000, 0),3) -> 0 | F45: =ROUND(IF(F15>0, ((0.0014*F15+13.97)/1.15)*(10^12)/(1000*29308)/1000000, 0),3) -> 0 | G45: =ROUND(IF(G15>0, ((0.0014*G15+13.97)/1.15)*(10^12)/(1000*29308)/1000000, 0),3) -> 0 | H45: =ROUND(IF(H15>0, ((0.0014*H15+13.97)/1.15)*(10^12)/(1000*29308)/1000000, 0),3) -> 0 | I45: =ROUND(IF(I15>0, ((0.0014*I15+13.97)/1.15)*(10^12)/(1000*29308)/1000000, 0),3) -> 0.487 | J45: =ROUND(IF(J15>0, ((0.0014*J15+13.97)/1.15)*(10^12)/(1000*29308)/1000000, 0),3) -> 0.468 | ... AF45: =ROUND(IF(AF15>0, ((0.0014*AF15+13.97)/1.15)*(10^12)/(1000*29308)/1000000, 0),3) -> 0
A46: Hardcoal | B46: FR | C46: =ROUND(IF(C16>0, ((0.0014*C16+13.97)/1.15)*(10^12)/(1000*29308)/1000000, 0),3) -> 0 | D46: =ROUND(IF(D16>0, ((0.0014*D16+13.97)/1.15)*(10^12)/(1000*29308)/1000000, 0),3) -> 0.475 | E46: =ROUND(IF(E16>0, ((0.0014*E16+13.97)/1.15)*(10^12)/(1000*29308)/1000000, 0),3) -> 0.427 | F46: =ROUND(IF(F16>0, ((0.0014*F16+13.97)/1.15)*(10^12)/(1000*29308)/1000000, 0),3) -> 0 | G46: =ROUND(IF(G16>0, ((0.0014*G16+13.97)/1.15)*(10^12)/(1000*29308)/1000000, 0),3) -> 0.429 | H46: =ROUND(IF(H16>0, ((0.0014*H16+13.97)/1.15)*(10^12)/(1000*29308)/1000000, 0),3) -> 0.482 | I46: =ROUND(IF(I16>0, ((0.0014*I16+13.97)/1.15)*(10^12)/(1000*29308)/1000000, 0),3) -> 0.435 | J46: =ROUND(IF(J16>0, ((0.0014*J16+13.97)/1.15)*(10^12)/(1000*29308)/1000000, 0),3) -> 0.489 | ... AF46: =ROUND(IF(AF16>0, ((0.0014*AF16+13.97)/1.15)*(10^12)/(1000*29308)/1000000, 0),3) -> 0
A47: Hardcoal | B47: GR | C47: =ROUND(IF(C17>0, ((0.0014*C17+13.97)/1.15)*(10^12)/(1000*29308)/1000000, 0),3) -> 0.506 | D47: =ROUND(IF(D17>0, ((0.0014*D17+13.97)/1.15)*(10^12)/(1000*29308)/1000000, 0),3) -> 0.464 | E47: =ROUND(IF(E17>0, ((0.0014*E17+13.97)/1.15)*(10^12)/(1000*29308)/1000000, 0),3) -> 0 | F47: =ROUND(IF(F17>0, ((0.0014*F17+13.97)/1.15)*(10^12)/(1000*29308)/1000000, 0),3) -> 0.433 | G47: =ROUND(IF(G17>0, ((0.0014*G17+13.97)/1.15)*(10^12)/(1000*29308)/1000000, 0),3) -> 0 | H47: =ROUND(IF(H17>0, ((0.0014*H17+13.97)/1.15)*(10^12)/(1000*29308)/1000000, 0),3) -> 0.47 | I47: =ROUND(IF(I17>0, ((0.0014*I17+13.97)/1.15)*(10^12)/(1000*29308)/1000000, 0),3) -> 0.484 | J47: =ROUND(IF(J17>0, ((0.0014*J17+13.97)/1.15)*(10^12)/(1000*29308)/1000000, 0),3) -> 0 | ... AF47: =ROUND(IF(AF17>0, ((0.0014*AF17+13.97)/1.15)*(10^12)/(1000*29308)/1000000, 0),3) -> 0.451
... A65: Hardcoal | B65: UK | C65: =ROUND(IF(C35>0, ((0.0014*C35+13.97)/1.15)*(10^12)/(1000*29308)/1000000, 0),3) -> 0.439 | D65: =ROUND(IF(D35>0, ((0.0014*D35+13.97)/1.15)*(10^12)/(1000*29308)/1000000, 0),3) -> 0.473 | E65: =ROUND(IF(E35>0, ((0.0014*E35+13.97)/1.15)*(10^12)/(1000*29308)/1000000, 0),3) -> 0.441 | F65: =ROUND(IF(F35>0, ((0.0014*F35+13.97)/1.15)*(10^12)/(1000*29308)/1000000, 0),3) -> 0 | G65: =ROUND(IF(G35>0, ((0.0014*G35+13.97)/1.15)*(10^12)/(1000*29308)/1000000, 0),3) -> 0.462 | H65: =ROUND(IF(H35>0, ((0.0014*H35+13.97)/1.15)*(10^12)/(1000*29308)/1000000, 0),3) -> 0.47 | I65: =ROUND(IF(I35>0, ((0.0014*I35+13.97)/1.15)*(10^12)/(1000*29308)/1000000, 0),3) -> 0.454 | J65: =ROUND(IF(J35>0, ((0.0014*J35+13.97)/1.15)*(10^12)/(1000*29308)/1000000, 0),3) -> 0.45 | ... AF65: =ROUND(IF(AF35>0, ((0.0014*AF35+13.97)/1.15)*(10^12)/(1000*29308)/1000000, 0),3) -> 0
A66: Biomass | B66: AT | C66: =C36 -> 0.475 | D66: =D36 -> 0 | E66: =E36 -> 0.446 | F66: =F36 -> 0.457 | G66: =G36 -> 0.433 | H66: =H36 -> 0.425 | I66: =I36 -> 0.434 | J66: =J36 -> 0.455 | ... AF66: =AF36 -> 0
A67: Biomass | B67: BE | C67: =C37 -> 0.427 | D67: =D37 -> 0.446 | E67: =E37 -> 0 | F67: =F37 -> 0 | G67: =G37 -> 0.435 | H67: =H37 -> 0.446 | I67: =I37 -> 0.431 | J67: =J37 -> 0.443 | ... AF67: =AF37 -> 0
A68: Biomass | B68: BG | C68: =C38 -> 0 | D68: =D38 -> 0.457 | E68: =E38 -> 0 | F68: =F38 -> 0 | G68: =G38 -> 0.473 | H68: =H38 -> 0.46 | I68: =I38 -> 0.475 | J68: =J38 -> 0 | ... AF68: =AF38 -> 0.432
A69: Biomass | B69: CH | C69: =C39 -> 0.429 | D69: =D39 -> 0.433 | E69: =E39 -> 0.435 | F69: =F39 -> 0.473 | G69: =G39 -> 0 | H69: =H39 -> 0.44 | I69: =I39 -> 0.435 | J69: =J39 -> 0.457 | ... AF69: =AF39 -> 0
A70: Biomass | B70: CZ | C70: =C40 -> 0.482 | D70: =D40 -> 0.425 | E70: =E40 -> 0.446 | F70: =F40 -> 0.46 | G70: =G40 -> 0.44 | H70: =H40 -> 0 | I70: =I40 -> 0.43 | J70: =J40 -> 0.447 | ... AF70: =AF40 -> 0
A71: Biomass | B71: DE | C71: =C41 -> 0.435 | D71: =D41 -> 0.434 | E71: =E41 -> 0.431 | F71: =F41 -> 0.475 | G71: =G41 -> 0.435 | H71: =H41 -> 0.43 | I71: =I41 -> 0 | J71: =J41 -> 0.437 | ... AF71: =AF41 -> 0
A72: Biomass | B72: DK | C72: =C42 -> 0.489 | D72: =D42 -> 0.455 | E72: =E42 -> 0.443 | F72: =F42 -> 0 | G72: =G42 -> 0.457 | H72: =H42 -> 0.447 | I72: =I42 -> 0.437 | J72: =J42 -> 0 | ... AF72: =AF42 -> 0
A73: Biomass | B73: EE | C73: =C43 -> 0 | D73: =D43 -> 0 | E73: =E43 -> 0 | F73: =F43 -> 0 | G73: =G43 -> 0 | H73: =H43 -> 0.464 | I73: =I43 -> 0.468 | J73: =J43 -> 0.455 | ... AF73: =AF43 -> 0
A74: Biomass | B74: ES | C74: =C44 -> 0.424 | D74: =D44 -> 0.483 | E74: =E44 -> 0.47 | F74: =F44 -> 0 | G74: =G44 -> 0.465 | H74: =H44 -> 0 | I74: =I44 -> 0.482 | J74: =J44 -> 0 | ... AF74: =AF44 -> 0
A75: Biomass | B75: FI | C75: =C45 -> 0 | D75: =D45 -> 0 | E75: =E45 -> 0 | F75: =F45 -> 0 | G75: =G45 -> 0 | H75: =H45 -> 0 | I75: =I45 -> 0.487 | J75: =J45 -> 0.468 | ... AF75: =AF45 -> 0
...

Sheet Par_TradeCapacity
A1: TradeCapacity{y in YEAR, f in FUEL, r in REGION1, rr in REGION2}
A2: Defines the capacities for trade between two regions in a specific year and for a specific fuel.
A3: Unit: GW for Power; PJ for Gas
C5: AT | D5: BE | E5: BG | F5: CH | G5: CZ | H5: DE | I5: DK | J5: ES | K5: FI | L5: FR | M5: GR | N5: HR | O5: HU | P5: IE | Q5: IT | R5: LU | S5: NONEU_Balkan | T5: NL | U5: NO | V5: PL | W5: PT | X5: RO | Y5: SE | Z5: SI | AA5: SK | AB5: UK | AC5: EE | AD5: LT | AE5: LV | AF5: TR | AH5: TR
C6: 2018 | D6: 2018 | E6: 2018 | F6: 2018 | G6: 2018 | H6: 2018 | I6: 2018 | J6: 2018 | K6: 2018 | L6: 2018 | M6: 2018 | N6: 2018 | O6: 2018 | P6: 2018 | Q6: 2018 | R6: 2018 | S6: 2018 | T6: 2018 | U6: 2018 | V6: 2018 | W6: 2018 | X6: 2018 | Y6: 2018 | Z6: 2018 | AA6: 2018 | AB6: 2018 | AC6: 2018 | AD6: 2018 | AE6: 2018 | AF6: 2018
A7: Power | B7: AT | C7: 0 | F7: 0.43425 | G7: 0.9 | H7: 2 | O7: 0.8 | Q7: 0.071 | Z7: 0.95008333
A8: Power | B8: BE | D8: 0 | L8: 1.5 | T8: 1.426 | AH8: 1
A9: Power | B9: BG | E9: 0 | M9: 0.35 | S9: 0.35 | X9: 0.15 | AF9: 1
A10: Power | B10: CH | C10: 1.2 | F10: 0 | H10: 3.5 | L10: 1.1 | Q10: 1.336
A11: Power | B11: CZ | C11: 0.8 | G11: 0 | H11: 1.775 | V11: 0.1 | AA11: 1.7
A12: Power | B12: DE | C12: 2.2 | F12: 3.5 | G12: 1.1 | H12: 0 | I12: 3.1 | L12: 1.675 | R12: 0.98 | T12: 2.85 | U12: 1.444 | V12: 0.1 | Y12: 0.35395833
A13: Power | B13: DK | H13: 3.1 | I13: 0 | T13: 0.7 | U13: 1.7 | Y13: 2.44 | AB13: 1.4
A14: Power | B14: ES | J14: 0 | L14: 2.9 | W14: 4.1
A15: Power | B15: FI | K15: 0 | Y15: 1.95 | AC15: 0.365
A16: Power | B16: FR | D16: 2.6 | F16: 3.2 | H16: 1.8 | J16: 2.8 | L16: 0 | Q16: 0.866 | AB16: 2 | AH16: 1
A17: Power | B17: GR | E17: 0.5 | M17: 0 | Q17: 0.5 | S17: 0.3 | AF17: 1
A18: Power | B18: HR | N18: 0 | O18: 1 | S18: 1.1 | Z18: 1
A19: Power | B19: HU | C19: 0.8 | N19: 1.2 | O19: 0 | S19: 0.7 | X19: 0.4 | AA19: 0.8
A20: Power | B20: IE | P20: 0 | AB20: 0.45
A21: Power | B21: IT | C21: 0.1 | F21: 1.91 | L21: 1.16 | M21: 0.5 | Q21: 0 | Z21: 0.18
A22: Power | B22: LU | H22: 0.98 | R22: 0
A23: Power | B23: NONEU_Balkan | E23: 0.35 | M23: 0.3 | N23: 1.1 | O23: 0.7 | S23: 0 | X23: 0.2
A24: Power | B24: NL | D24: 1.426 | H24: 2.4 | I24: 0.7 | T24: 0 | U24: 0.723 | AB24: 1.016
A25: Power | B25: NO | H25: 1.444 | I25: 1.7 | T25: 0.723 | U25: 0 | Y25: 3.445 | AB25: 2.8
A26: Power | B26: PL | G26: 0.1 | H26: 0.225 | V26: 0 | Y26: 0.26591667 | AA26: 0.6
A27: Power | B27: PT | J27: 4.5 | W27: 0
A28: Power | B28: RO | E28: 0.6 | O28: 0.7 | S28: 0.2 | X28: 0
A29: Power | B29: SE | H29: 0.61 | I29: 2.44 | K29: 2.25 | U29: 3.695 | V29: 0.34166667 | Y29: 0
A30: Power | B30: SI | C30: 0.95 | N30: 1.2 | Q30: 0.203 | Z30: 0
A31: Power | B31: SK | G31: 1.2 | O31: 1.3 | V31: 0.5 | AA31: 0
A32: Power | B32: UK | I32: 1.4 | L32: 2 | P32: 0.45 | T32: 1.016 | U32: 2.8 | AB32: 0
A33: Power | B33: EE | K33: 0.365 | AC33: 0 | AE33: 0.8
A34: Power | B34: LT | AD34: 0 | AE34: 1.5
A35: Power | B35: LV | AC35: 0.75 | AD35: 1.45 | AE35: 0 | AH35: 0
A36: Power | B36: TR | E36: 1 | M36: 1 | AF36: 0
A37: gas_natural | B37: FR | D37: 0 | F37: 371.51679 | H37: 0 | J37: 235.4081 | AH37: 606.92489
A38: gas_natural | B38: AT | H38: 568.68891 | O38: 185.05788 | Q38: 1633.042 | Z38: 160.50552 | AA38: 353.14069 | AH38: 2900.435
A39: gas_natural | B39: BE | H39: 446.66921 | L39: 1241.2427 | R39: 54.215199 | T39: 560.98464 | AB39: 1146.2235 | AH39: 3449.3352
A40: gas_natural | B40: BG | M40: 0 | S40: 0 | X40: 20.516173 | AF40: 0 | AH40: 20.516173
A41: gas_natural | B41: CH | Q41: 888.22233 | AH41: 888.22233
...

Sheet Par_TradeCapacityGrowthCosts
A1: TradeCapacityGrowthCosts{f in FUEL, r in REGION1, rr in REGION2}
A2: Costs of expanding trade capacity.
A3: Unit: M€/GW
C5: AL | D5: AT | E5: BA | F5: BE | G5: BG | H5: CH | I5: CZ | J5: DE | K5: DK | L5: ES | M5: FI | N5: FR | O5: GR | P5: HR | Q5: HU | R5: IE | S5: IT | T5: LU | U5: ME | V5: MK | W5: NL | X5: NO | Y5: PL | Z5: PT | AA5: RO | AB5: RS | AC5: SE | AD5: SI | AE5: SK | AF5: UK | AG5: EE | AH5: LT | AI5: LV | AJ5: UA | AK5: RU | AL5: BY | AM5: NONEU_Balkan | AN5: TR
A6: Power | B6: AL | C6: 2.1425 | D6: 2.1425 | E6: 2.1425 | F6: 2.1425 | G6: 2.1425 | H6: 2.1425 | I6: 2.1425 | J6: 2.1425 | K6: 2.1425 | L6: 2.1425 | M6: 2.1425 | N6: 2.1425 | O6: 2.1425 | P6: 2.1425 | Q6: 2.1425 | R6: 2.1425 | S6: 2.1425 | T6: 2.1425 | U6: 2.1425 | V6: 2.1425 | W6: 2.1425 | X6: 2.1425 | Y6: 2.1425 | Z6: 2.1425 | AA6: 2.1425 | AB6: 2.1425 | AC6: 2.1425 | AD6: 2.1425 | AE6: 2.1425 | AF6: 2.1425 | AG6: 2.1425 | AH6: 2.1425 | AI6: 2.1425 | AJ6: 2.1425 | AK6: 2.1425 | AL6: 2.1425 | AM6: 2.1425 | AN6: 2.1425
A7: Power | B7: AT | C7: 2.1425 | D7: 2.1425 | E7: 2.1425 | F7: 2.1425 | G7: 2.1425 | H7: 2.1425 | I7: 2.1425 | J7: 2.1425 | K7: 2.1425 | L7: 2.1425 | M7: 2.1425 | N7: 2.1425 | O7: 2.1425 | P7: 2.1425 | Q7: 2.1425 | R7: 2.1425 | S7: 2.1425 | T7: 2.1425 | U7: 2.1425 | V7: 2.1425 | W7: 2.1425 | X7: 2.1425 | Y7: 2.1425 | Z7: 2.1425 | AA7: 2.1425 | AB7: 2.1425 | AC7: 2.1425 | AD7: 2.1425 | AE7: 2.1425 | AF7: 2.1425 | AG7: 2.1425 | AH7: 2.1425 | AI7: 2.1425 | AJ7: 2.1425 | AK7: 2.1425 | AL7: 2.1425 | AM7: 2.1425 | AN7: 2.1425
A8: Power | B8: BA | C8: 2.1425 | D8: 2.1425 | E8: 2.1425 | F8: 2.1425 | G8: 2.1425 | H8: 2.1425 | I8: 2.1425 | J8: 2.1425 | K8: 2.1425 | L8: 2.1425 | M8: 2.1425 | N8: 2.1425 | O8: 2.1425 | P8: 2.1425 | Q8: 2.1425 | R8: 2.1425 | S8: 2.1425 | T8: 2.1425 | U8: 2.1425 | V8: 2.1425 | W8: 2.1425 | X8: 2.1425 | Y8: 2.1425 | Z8: 2.1425 | AA8: 2.1425 | AB8: 2.1425 | AC8: 2.1425 | AD8: 2.1425 | AE8: 2.1425 | AF8: 2.1425 | AG8: 2.1425 | AH8: 2.1425 | AI8: 2.1425 | AJ8: 2.1425 | AK8: 2.1425 | AL8: 2.1425 | AM8: 2.1425 | AN8: 2.1425
A9: Power | B9: BE | C9: 2.1425 | D9: 2.1425 | E9: 2.1425 | F9: 2.1425 | G9: 2.1425 | H9: 2.1425 | I9: 2.1425 | J9: 2.1425 | K9: 2.1425 | L9: 2.1425 | M9: 2.1425 | N9: 2.1425 | O9: 2.1425 | P9: 2.1425 | Q9: 2.1425 | R9: 2.1425 | S9: 2.1425 | T9: 2.1425 | U9: 2.1425 | V9: 2.1425 | W9: 2.1425 | X9: 2.1425 | Y9: 2.1425 | Z9: 2.1425 | AA9: 2.1425 | AB9: 2.1425 | AC9: 2.1425 | AD9: 2.1425 | AE9: 2.1425 | AF9: 2.1425 | AG9: 2.1425 | AH9: 2.1425 | AI9: 2.1425 | AJ9: 2.1425 | AK9: 2.1425 | AL9: 2.1425 | AM9: 2.1425 | AN9: 2.1425
A10: Power | B10: BG | C10: 2.1425 | D10: 2.1425 | E10: 2.1425 | F10: 2.1425 | G10: 2.1425 | H10: 2.1425 | I10: 2.1425 | J10: 2.1425 | K10: 2.1425 | L10: 2.1425 | M10: 2.1425 | N10: 2.1425 | O10: 2.1425 | P10: 2.1425 | Q10: 2.1425 | R10: 2.1425 | S10: 2.1425 | T10: 2.1425 | U10: 2.1425 | V10: 2.1425 | W10: 2.1425 | X10: 2.1425 | Y10: 2.1425 | Z10: 2.1425 | AA10: 2.1425 | AB10: 2.1425 | AC10: 2.1425 | AD10: 2.1425 | AE10: 2.1425 | AF10: 2.1425 | AG10: 2.1425 | AH10: 2.1425 | AI10: 2.1425 | AJ10: 2.1425 | AK10: 2.1425 | AL10: 2.1425 | AM10: 2.1425 | AN10: 2.1425
A11: Power | B11: CH | C11: 2.1425 | D11: 2.1425 | E11: 2.1425 | F11: 2.1425 | G11: 2.1425 | H11: 2.1425 | I11: 2.1425 | J11: 2.1425 | K11: 2.1425 | L11: 2.1425 | M11: 2.1425 | N11: 2.1425 | O11: 2.1425 | P11: 2.1425 | Q11: 2.1425 | R11: 2.1425 | S11: 2.1425 | T11: 2.1425 | U11: 2.1425 | V11: 2.1425 | W11: 2.1425 | X11: 2.1425 | Y11: 2.1425 | Z11: 2.1425 | AA11: 2.1425 | AB11: 2.1425 | AC11: 2.1425 | AD11: 2.1425 | AE11: 2.1425 | AF11: 2.1425 | AG11: 2.1425 | AH11: 2.1425 | AI11: 2.1425 | AJ11: 2.1425 | AK11: 2.1425 | AL11: 2.1425 | AM11: 2.1425 | AN11: 2.1425
A12: Power | B12: CZ | C12: 2.1425 | D12: 2.1425 | E12: 2.1425 | F12: 2.1425 | G12: 2.1425 | H12: 2.1425 | I12: 2.1425 | J12: 2.1425 | K12: 2.1425 | L12: 2.1425 | M12: 2.1425 | N12: 2.1425 | O12: 2.1425 | P12: 2.1425 | Q12: 2.1425 | R12: 2.1425 | S12: 2.1425 | T12: 2.1425 | U12: 2.1425 | V12: 2.1425 | W12: 2.1425 | X12: 2.1425 | Y12: 2.1425 | Z12: 2.1425 | AA12: 2.1425 | AB12: 2.1425 | AC12: 2.1425 | AD12: 2.1425 | AE12: 2.1425 | AF12: 2.1425 | AG12: 2.1425 | AH12: 2.1425 | AI12: 2.1425 | AJ12: 2.1425 | AK12: 2.1425 | AL12: 2.1425 | AM12: 2.1425 | AN12: 2.1425
A13: Power | B13: DE | C13: 2.1425 | D13: 2.1425 | E13: 2.1425 | F13: 2.1425 | G13: 2.1425 | H13: 2.1425 | I13: 2.1425 | J13: 2.1425 | K13: 2.1425 | L13: 2.1425 | M13: 2.1425 | N13: 2.1425 | O13: 2.1425 | P13: 2.1425 | Q13: 2.1425 | R13: 2.1425 | S13: 2.1425 | T13: 2.1425 | U13: 2.1425 | V13: 2.1425 | W13: 2.1425 | X13: 2.1425 | Y13: 2.1425 | Z13: 2.1425 | AA13: 2.1425 | AB13: 2.1425 | AC13: 2.1425 | AD13: 2.1425 | AE13: 2.1425 | AF13: 2.1425 | AG13: 2.1425 | AH13: 2.1425 | AI13: 2.1425 | AJ13: 2.1425 | AK13: 2.1425 | AL13: 2.1425 | AM13: 2.1425 | AN13: 2.1425
A14: Power | B14: DK | C14: 2.1425 | D14: 2.1425 | E14: 2.1425 | F14: 2.1425 | G14: 2.1425 | H14: 2.1425 | I14: 2.1425 | J14: 2.1425 | K14: 2.1425 | L14: 2.1425 | M14: 2.1425 | N14: 2.1425 | O14: 2.1425 | P14: 2.1425 | Q14: 2.1425 | R14: 2.1425 | S14: 2.1425 | T14: 2.1425 | U14: 2.1425 | V14: 2.1425 | W14: 2.1425 | X14: 2.1425 | Y14: 2.1425 | Z14: 2.1425 | AA14: 2.1425 | AB14: 2.1425 | AC14: 2.1425 | AD14: 2.1425 | AE14: 2.1425 | AF14: 2.1425 | AG14: 2.1425 | AH14: 2.1425 | AI14: 2.1425 | AJ14: 2.1425 | AK14: 2.1425 | AL14: 2.1425 | AM14: 2.1425 | AN14: 2.1425
A15: Power | B15: ES | C15: 2.1425 | D15: 2.1425 | E15: 2.1425 | F15: 2.1425 | G15: 2.1425 | H15: 2.1425 | I15: 2.1425 | J15: 2.1425 | K15: 2.1425 | L15: 2.1425 | M15: 2.1425 | N15: 2.1425 | O15: 2.1425 | P15: 2.1425 | Q15: 2.1425 | R15: 2.1425 | S15: 2.1425 | T15: 2.1425 | U15: 2.1425 | V15: 2.1425 | W15: 2.1425 | X15: 2.1425 | Y15: 2.1425 | Z15: 2.1425 | AA15: 2.1425 | AB15: 2.1425 | AC15: 2.1425 | AD15: 2.1425 | AE15: 2.1425 | AF15: 2.1425 | AG15: 2.1425 | AH15: 2.1425 | AI15: 2.1425 | AJ15: 2.1425 | AK15: 2.1425 | AL15: 2.1425 | AM15: 2.1425 | AN15: 2.1425
A16: Power | B16: FI | C16: 2.1425 | D16: 2.1425 | E16: 2.1425 | F16: 2.1425 | G16: 2.1425 | H16: 2.1425 | I16: 2.1425 | J16: 2.1425 | K16: 2.1425 | L16: 2.1425 | M16: 2.1425 | N16: 2.1425 | O16: 2.1425 | P16: 2.1425 | Q16: 2.1425 | R16: 2.1425 | S16: 2.1425 | T16: 2.1425 | U16: 2.1425 | V16: 2.1425 | W16: 2.1425 | X16: 2.1425 | Y16: 2.1425 | Z16: 2.1425 | AA16: 2.1425 | AB16: 2.1425 | AC16: 2.1425 | AD16: 2.1425 | AE16: 2.1425 | AF16: 2.1425 | AG16: 2.1425 | AH16: 2.1425 | AI16: 2.1425 | AJ16: 2.1425 | AK16: 2.1425 | AL16: 2.1425 | AM16: 2.1425 | AN16: 2.1425
A17: Power | B17: FR | C17: 2.1425 | D17: 2.1425 | E17: 2.1425 | F17: 2.1425 | G17: 2.1425 | H17: 2.1425 | I17: 2.1425 | J17: 2.1425 | K17: 2.1425 | L17: 2.1425 | M17: 2.1425 | N17: 2.1425 | O17: 2.1425 | P17: 2.1425 | Q17: 2.1425 | R17: 2.1425 | S17: 2.1425 | T17: 2.1425 | U17: 2.1425 | V17: 2.1425 | W17: 2.1425 | X17: 2.1425 | Y17: 2.1425 | Z17: 2.1425 | AA17: 2.1425 | AB17: 2.1425 | AC17: 2.1425 | AD17: 2.1425 | AE17: 2.1425 | AF17: 2.1425 | AG17: 2.1425 | AH17: 2.1425 | AI17: 2.1425 | AJ17: 2.1425 | AK17: 2.1425 | AL17: 2.1425 | AM17: 2.1425 | AN17: 2.1425
... A43: Power | B43: TR | C43: 2.1425 | D43: 2.1425 | E43: 2.1425 | F43: 2.1425 | G43: 2.1425 | H43: 2.1425 | I43: 2.1425 | J43: 2.1425 | K43: 2.1425 | L43: 2.1425 | M43: 2.1425 | N43: 2.1425 | O43: 2.1425 | P43: 2.1425 | Q43: 2.1425 | R43: 2.1425 | S43: 2.1425 | T43: 2.1425 | U43: 2.1425 | V43: 2.1425 | W43: 2.1425 | X43: 2.1425 | Y43: 2.1425 | Z43: 2.1425 | AA43: 2.1425 | AB43: 2.1425 | AC43: 2.1425 | AD43: 2.1425 | AE43: 2.1425 | AF43: 2.1425 | AG43: 2.1425 | AH43: 2.1425 | AI43: 2.1425 | AJ43: 2.1425 | AK43: 2.1425 | AL43: 2.1425 | AM43: 2.1425 | AN43: 2.1425

Sheet Par_GrowthRateTradeCapacity
A1: GrowthRateTradeCapacity{y in YEAR, f in FUEL, r in REGION1, rr in REGION2}
A2: Defines by how much the trade capacity between two regions can grow
A3: Unit: Factor
D5: AL | E5: AT | F5: BA | G5: BE | H5: BG | I5: CH | J5: CZ | K5: DE | L5: DK | M5: ES | N5: FI | O5: FR | P5: GR | Q5: HR | R5: HU | S5: IE | T5: IT | U5: LU | V5: ME | W5: MK | X5: NL | Y5: NO | Z5: PL | AA5: PT | AB5: RO | AC5: RS | AD5: SE | AE5: SI | AF5: SK | AG5: UK | AH5: EE | AI5: LT | AJ5: LV | AK5: UA | AL5: RU | AM5: BY
A6: 2018 | B6: Power | C6: AL | D6: 2 | E6: 2 | F6: 2 | G6: 2 | H6: 2 | I6: 2 | J6: 2 | K6: 2 | L6: 2 | M6: 2 | N6: 2 | O6: 2 | P6: 2 | Q6: 2 | R6: 2 | S6: 2 | T6: 2 | U6: 2 | V6: 2 | W6: 2 | X6: 2 | Y6: 2 | Z6: 2 | AA6: 2 | AB6: 2 | AC6: 2 | AD6: 2 | AE6: 2 | AF6: 2 | AG6: 2 | AH6: 2 | AI6: 2 | AJ6: 2 | AK6: 2 | AL6: 2 | AM6: 2
A7: 2018 | B7: Power | C7: AT | D7: 2 | E7: 2 | F7: 2 | G7: 2 | H7: 2 | I7: 2 | J7: 2 | K7: 2 | L7: 2 | M7: 2 | N7: 2 | O7: 2 | P7: 2 | Q7: 2 | R7: 2 | S7: 2 | T7: 2 | U7: 2 | V7: 2 | W7: 2 | X7: 2 | Y7: 2 | Z7: 2 | AA7: 2 | AB7: 2 | AC7: 2 | AD7: 2 | AE7: 2 | AF7: 2 | AG7: 2 | AH7: 2 | AI7: 2 | AJ7: 2 | AK7: 2 | AL7: 2 | AM7: 2
A8: 2018 | B8: Power | C8: BA | D8: 2 | E8: 2 | F8: 2 | G8: 2 | H8: 2 | I8: 2 | J8: 2 | K8: 2 | L8: 2 | M8: 2 | N8: 2 | O8: 2 | P8: 2 | Q8: 2 | R8: 2 | S8: 2 | T8: 2 | U8: 2 | V8: 2 | W8: 2 | X8: 2 | Y8: 2 | Z8: 2 | AA8: 2 | AB8: 2 | AC8: 2 | AD8: 2 | AE8: 2 | AF8: 2 | AG8: 2 | AH8: 2 | AI8: 2 | AJ8: 2 | AK8: 2 | AL8: 2 | AM8: 2
A9: 2018 | B9: Power | C9: BE | D9: 2 | E9: 2 | F9: 2 | G9: 2 | H9: 2 | I9: 2 | J9: 2 | K9: 2 | L9: 2 | M9: 2 | N9: 2 | O9: 2 | P9: 2 | Q9: 2 | R9: 2 | S9: 2 | T9: 2 | U9: 2 | V9: 2 | W9: 2 | X9: 2 | Y9: 2 | Z9: 2 | AA9: 2 | AB9: 2 | AC9: 2 | AD9: 2 | AE9: 2 | AF9: 2 | AG9: 2 | AH9: 2 | AI9: 2 | AJ9: 2 | AK9: 2 | AL9: 2 | AM9: 2
A10: 2018 | B10: Power | C10: BG | D10: 2 | E10: 2 | F10: 2 | G10: 2 | H10: 2 | I10: 2 | J10: 2 | K10: 2 | L10: 2 | M10: 2 | N10: 2 | O10: 2 | P10: 2 | Q10: 2 | R10: 2 | S10: 2 | T10: 2 | U10: 2 | V10: 2 | W10: 2 | X10: 2 | Y10: 2 | Z10: 2 | AA10: 2 | AB10: 2 | AC10: 2 | AD10: 2 | AE10: 2 | AF10: 2 | AG10: 2 | AH10: 2 | AI10: 2 | AJ10: 2 | AK10: 2 | AL10: 2 | AM10: 2
A11: 2018 | B11: Power | C11: CH | D11: 2 | E11: 2 | F11: 2 | G11: 2 | H11: 2 | I11: 2 | J11: 2 | K11: 2 | L11: 2 | M11: 2 | N11: 2 | O11: 2 | P11: 2 | Q11: 2 | R11: 2 | S11: 2 | T11: 2 | U11: 2 | V11: 2 | W11: 2 | X11: 2 | Y11: 2 | Z11: 2 | AA11: 2 | AB11: 2 | AC11: 2 | AD11: 2 | AE11: 2 | AF11: 2 | AG11: 2 | AH11: 2 | AI11: 2 | AJ11: 2 | AK11: 2 | AL11: 2 | AM11: 2
A12: 2018 | B12: Power | C12: CZ | D12: 2 | E12: 2 | F12: 2 | G12: 2 | H12: 2 | I12: 2 | J12: 2 | K12: 2 | L12: 2 | M12: 2 | N12: 2 | O12: 2 | P12: 2 | Q12: 2 | R12: 2 | S12: 2 | T12: 2 | U12: 2 | V12: 2 | W12: 2 | X12: 2 | Y12: 2 | Z12: 2 | AA12: 2 | AB12: 2 | AC12: 2 | AD12: 2 | AE12: 2 | AF12: 2 | AG12: 2 | AH12: 2 | AI12: 2 | AJ12: 2 | AK12: 2 | AL12: 2 | AM12: 2
A13: 2018 | B13: Power | C13: DE | D13: 2 | E13: 2 | F13: 2 | G13: 2 | H13: 2 | I13: 2 | J13: 2 | K13: 2 | L13: 2 | M13: 2 | N13: 2 | O13: 2 | P13: 2 | Q13: 2 | R13: 2 | S13: 2 | T13: 2 | U13: 2 | V13: 2 | W13: 2 | X13: 2 | Y13: 2 | Z13: 2 | AA13: 2 | AB13: 2 | AC13: 2 | AD13: 2 | AE13: 2 | AF13: 2 | AG13: 2 | AH13: 2 | AI13: 2 | AJ13: 2 | AK13: 2 | AL13: 2 | AM13: 2
A14: 2018 | B14: Power | C14: DK | D14: 2 | E14: 2 | F14: 2 | G14: 2 | H14: 2 | I14: 2 | J14: 2 | K14: 2 | L14: 2 | M14: 2 | N14: 2 | O14: 2 | P14: 2 | Q14: 2 | R14: 2 | S14: 2 | T14: 2 | U14: 2 | V14: 2 | W14: 2 | X14: 2 | Y14: 2 | Z14: 2 | AA14: 2 | AB14: 2 | AC14: 2 | AD14: 2 | AE14: 2 | AF14: 2 | AG14: 2 | AH14: 2 | AI14: 2 | AJ14: 2 | AK14: 2 | AL14: 2 | AM14: 2
A15: 2018 | B15: Power | C15: ES | D15: 2 | E15: 2 | F15: 2 | G15: 2 | H15: 2 | I15: 2 | J15: 2 | K15: 2 | L15: 2 | M15: 2 | N15: 2 | O15: 2 | P15: 2 | Q15: 2 | R15: 2 | S15: 2 | T15: 2 | U15: 2 | V15: 2 | W15: 2 | X15: 2 | Y15: 2 | Z15: 2 | AA15: 2 | AB15: 2 | AC15: 2 | AD15: 2 | AE15: 2 | AF15: 2 | AG15: 2 | AH15: 2 | AI15: 2 | AJ15: 2 | AK15: 2 | AL15: 2 | AM15: 2
A16: 2018 | B16: Power | C16: FI | D16: 2 | E16: 2 | F16: 2 | G16: 2 | H16: 2 | I16: 2 | J16: 2 | K16: 2 | L16: 2 | M16: 2 | N16: 2 | O16: 2 | P16: 2 | Q16: 2 | R16: 2 | S16: 2 | T16: 2 | U16: 2 | V16: 2 | W16: 2 | X16: 2 | Y16: 2 | Z16: 2 | AA16: 2 | AB16: 2 | AC16: 2 | AD16: 2 | AE16: 2 | AF16: 2 | AG16: 2 | AH16: 2 | AI16: 2 | AJ16: 2 | AK16: 2 | AL16: 2 | AM16: 2
A17: 2018 | B17: Power | C17: FR | D17: 2 | E17: 2 | F17: 2 | G17: 2 | H17: 2 | I17: 2 | J17: 2 | K17: 2 | L17: 2 | M17: 2 | N17: 2 | O17: 2 | P17: 2 | Q17: 2 | R17: 2 | S17: 2 | T17: 2 | U17: 2 | V17: 2 | W17: 2 | X17: 2 | Y17: 2 | Z17: 2 | AA17: 2 | AB17: 2 | AC17: 2 | AD17: 2 | AE17: 2 | AF17: 2 | AG17: 2 | AH17: 2 | AI17: 2 | AJ17: 2 | AK17: 2 | AL17: 2 | AM17: 2
... A41: 2018 | B41: Power | C41: BY | D41: 2 | E41: 2 | F41: 2 | G41: 2 | H41: 2 | I41: 2 | J41: 2 | K41: 2 | L41: 2 | M41: 2 | N41: 2 | O41: 2 | P41: 2 | Q41: 2 | R41: 2 | S41: 2 | T41: 2 | U41: 2 | V41: 2 | W41: 2 | X41: 2 | Y41: 2 | Z41: 2 | AA41: 2 | AB41: 2 | AC41: 2 | AD41: 2 | AE41: 2 | AF41: 2 | AG41: 2 | AH41: 2 | AI41: 2 | AJ41: 2 | AK41: 2 | AL41: 2 | AM41: 2

Sheet Par_AnnualExogenousEmission
A1: AnnualExogenousEmission{r in REGION, e in EMISSION, y in YEAR)
A2: Amount of external Emissions for a year in a certain region.
A3: Unit: Megatonnes
A5: Region | B5: Emission | C5: 2018 | D5: 2020 | E5: 2025 | F5: 2030 | G5: 2035 | H5: 2040 | I5: 2045 | J5: 2050

Sheet Par_AnnualEmissionLimit
A1: AnnualEmissionLimit{e in EMISSION, y in YEAR}
A2: Limits the maximum amount of Emissions in a year.
A3: Unit: Megatonnes
B5: 2018 | C5: 2020 | D5: 2025 | E5: 2030 | F5: 2035 | G5: 2040 | H5: 2045 | I5: 2050
A6: CO2 | B6: 99999 | C6: 99999 | D6: 99999 | E6: 99999 | F6: 99999 | G6: 99999 | H6: 99999 | I6: 99999

Sheet Par_AnnualSectoralEmissionLimit
A1: AnnualSectoralEmissionLimit{e in EMISSION, se in SECTOR, y in YEAR}
A2: Limits the maximum amount of Emissions for a specific sector and region in a year.
A3: Unit: Megatonnes
A5: Emission | B5: Sector | C5: 2018 | D5: 2020 | E5: 2025 | F5: 2030 | G5: 2035 | H5: 2040 | I5: 2045 | J5: 2050
